{"uid":"33f3e23282d70c15","name":"test_network_cut_without_ip_change","fullName":"tests.integration.ha_tests.test_self_healing#test_network_cut_without_ip_change","historyId":"c42817a2584f9afe9bfa320de7305305","time":{"start":1715480594787,"stop":1715480888933,"duration":294146},"description":"Completely cut and restore network (situation when the unit IP doesn't change).","descriptionHtml":"<p>Completely cut and restore network (situation when the unit IP doesn't change).</p>\n","status":"broken","statusMessage":"tenacity.RetryError: RetryError[<Future at 0x7f5c89b5b8e0 state=finished raised AssertionError>]","statusTrace":"Traceback (most recent call last):\n  File \"/home/runner/work/postgresql-operator/postgresql-operator/tests/integration/ha_tests/helpers.py\", line 109, in are_writes_increasing\n    more_writes[member] > count\nAssertionError: test.postgresql-2: writes not continuing to DB (current writes: 260 - previous writes: 260)\n\nThe above exception was the direct cause of the following exception:\n\nTraceback (most recent call last):\n  File \"/home/runner/work/postgresql-operator/postgresql-operator/.tox/integration/lib/python3.10/site-packages/_pytest/runner.py\", line 341, in from_call\n    result: Optional[TResult] = func()\n  File \"/home/runner/work/postgresql-operator/postgresql-operator/.tox/integration/lib/python3.10/site-packages/_pytest/runner.py\", line 241, in <lambda>\n    lambda: runtest_hook(item=item, **kwds), when=when, reraise=reraise\n  File \"/home/runner/work/postgresql-operator/postgresql-operator/.tox/integration/lib/python3.10/site-packages/pluggy/_hooks.py\", line 513, in __call__\n    return self._hookexec(self.name, self._hookimpls.copy(), kwargs, firstresult)\n  File \"/home/runner/work/postgresql-operator/postgresql-operator/.tox/integration/lib/python3.10/site-packages/pluggy/_manager.py\", line 120, in _hookexec\n    return self._inner_hookexec(hook_name, methods, kwargs, firstresult)\n  File \"/home/runner/work/postgresql-operator/postgresql-operator/.tox/integration/lib/python3.10/site-packages/pluggy/_callers.py\", line 182, in _multicall\n    return outcome.get_result()\n  File \"/home/runner/work/postgresql-operator/postgresql-operator/.tox/integration/lib/python3.10/site-packages/pluggy/_result.py\", line 100, in get_result\n    raise exc.with_traceback(exc.__traceback__)\n  File \"/home/runner/work/postgresql-operator/postgresql-operator/.tox/integration/lib/python3.10/site-packages/pluggy/_callers.py\", line 167, in _multicall\n    teardown.throw(outcome._exception)\n  File \"/home/runner/work/postgresql-operator/postgresql-operator/.tox/integration/lib/python3.10/site-packages/_pytest/threadexception.py\", line 87, in pytest_runtest_call\n    yield from thread_exception_runtest_hook()\n  File \"/home/runner/work/postgresql-operator/postgresql-operator/.tox/integration/lib/python3.10/site-packages/_pytest/threadexception.py\", line 63, in thread_exception_runtest_hook\n    yield\n  File \"/home/runner/work/postgresql-operator/postgresql-operator/.tox/integration/lib/python3.10/site-packages/pluggy/_callers.py\", line 167, in _multicall\n    teardown.throw(outcome._exception)\n  File \"/home/runner/work/postgresql-operator/postgresql-operator/.tox/integration/lib/python3.10/site-packages/_pytest/unraisableexception.py\", line 90, in pytest_runtest_call\n    yield from unraisable_exception_runtest_hook()\n  File \"/home/runner/work/postgresql-operator/postgresql-operator/.tox/integration/lib/python3.10/site-packages/_pytest/unraisableexception.py\", line 65, in unraisable_exception_runtest_hook\n    yield\n  File \"/home/runner/work/postgresql-operator/postgresql-operator/.tox/integration/lib/python3.10/site-packages/pluggy/_callers.py\", line 167, in _multicall\n    teardown.throw(outcome._exception)\n  File \"/home/runner/work/postgresql-operator/postgresql-operator/.tox/integration/lib/python3.10/site-packages/_pytest/logging.py\", line 850, in pytest_runtest_call\n    yield from self._runtest_for(item, \"call\")\n  File \"/home/runner/work/postgresql-operator/postgresql-operator/.tox/integration/lib/python3.10/site-packages/_pytest/logging.py\", line 833, in _runtest_for\n    yield\n  File \"/home/runner/work/postgresql-operator/postgresql-operator/.tox/integration/lib/python3.10/site-packages/pluggy/_callers.py\", line 167, in _multicall\n    teardown.throw(outcome._exception)\n  File \"/home/runner/work/postgresql-operator/postgresql-operator/.tox/integration/lib/python3.10/site-packages/_pytest/capture.py\", line 878, in pytest_runtest_call\n    return (yield)\n  File \"/home/runner/work/postgresql-operator/postgresql-operator/.tox/integration/lib/python3.10/site-packages/pluggy/_callers.py\", line 167, in _multicall\n    teardown.throw(outcome._exception)\n  File \"/home/runner/work/postgresql-operator/postgresql-operator/.tox/integration/lib/python3.10/site-packages/_pytest/skipping.py\", line 257, in pytest_runtest_call\n    return (yield)\n  File \"/home/runner/work/postgresql-operator/postgresql-operator/.tox/integration/lib/python3.10/site-packages/pluggy/_callers.py\", line 103, in _multicall\n    res = hook_impl.function(*args)\n  File \"/home/runner/work/postgresql-operator/postgresql-operator/.tox/integration/lib/python3.10/site-packages/_pytest/runner.py\", line 183, in pytest_runtest_call\n    raise e\n  File \"/home/runner/work/postgresql-operator/postgresql-operator/.tox/integration/lib/python3.10/site-packages/_pytest/runner.py\", line 173, in pytest_runtest_call\n    item.runtest()\n  File \"/home/runner/work/postgresql-operator/postgresql-operator/.tox/integration/lib/python3.10/site-packages/_pytest/python.py\", line 1627, in runtest\n    self.ihook.pytest_pyfunc_call(pyfuncitem=self)\n  File \"/home/runner/work/postgresql-operator/postgresql-operator/.tox/integration/lib/python3.10/site-packages/pluggy/_hooks.py\", line 513, in __call__\n    return self._hookexec(self.name, self._hookimpls.copy(), kwargs, firstresult)\n  File \"/home/runner/work/postgresql-operator/postgresql-operator/.tox/integration/lib/python3.10/site-packages/pluggy/_manager.py\", line 120, in _hookexec\n    return self._inner_hookexec(hook_name, methods, kwargs, firstresult)\n  File \"/home/runner/work/postgresql-operator/postgresql-operator/.tox/integration/lib/python3.10/site-packages/pluggy/_callers.py\", line 182, in _multicall\n    return outcome.get_result()\n  File \"/home/runner/work/postgresql-operator/postgresql-operator/.tox/integration/lib/python3.10/site-packages/pluggy/_result.py\", line 100, in get_result\n    raise exc.with_traceback(exc.__traceback__)\n  File \"/home/runner/work/postgresql-operator/postgresql-operator/.tox/integration/lib/python3.10/site-packages/pluggy/_callers.py\", line 103, in _multicall\n    res = hook_impl.function(*args)\n  File \"/home/runner/work/postgresql-operator/postgresql-operator/.tox/integration/lib/python3.10/site-packages/_pytest/python.py\", line 162, in pytest_pyfunc_call\n    result = testfunction(**testargs)\n  File \"/home/runner/work/postgresql-operator/postgresql-operator/.tox/integration/lib/python3.10/site-packages/pytest_asyncio/plugin.py\", line 529, in inner\n    _loop.run_until_complete(task)\n  File \"/usr/lib/python3.10/asyncio/base_events.py\", line 649, in run_until_complete\n    return future.result()\n  File \"/home/runner/work/postgresql-operator/postgresql-operator/tests/integration/ha_tests/test_self_healing.py\", line 518, in test_network_cut_without_ip_change\n    await are_writes_increasing(ops_test, primary_name, use_ip_from_inside=True)\n  File \"/home/runner/work/postgresql-operator/postgresql-operator/tests/integration/ha_tests/helpers.py\", line 100, in are_writes_increasing\n    for attempt in Retrying(stop=stop_after_delay(60 * 3), wait=wait_fixed(3)):\n  File \"/home/runner/work/postgresql-operator/postgresql-operator/.tox/integration/lib/python3.10/site-packages/tenacity/__init__.py\", line 347, in __iter__\n    do = self.iter(retry_state=retry_state)\n  File \"/home/runner/work/postgresql-operator/postgresql-operator/.tox/integration/lib/python3.10/site-packages/tenacity/__init__.py\", line 326, in iter\n    raise retry_exc from fut.exception()\ntenacity.RetryError: RetryError[<Future at 0x7f5c89b5b8e0 state=finished raised AssertionError>]","flaky":false,"newFailed":false,"newBroken":true,"newPassed":false,"retriesCount":0,"retriesStatusChange":false,"beforeStages":[{"name":"event_loop","time":{"start":1715477406727,"stop":1715477406728,"duration":1},"status":"passed","steps":[],"attachments":[],"parameters":[],"stepsCount":0,"shouldDisplayMessage":false,"attachmentsCount":0,"hasContent":false,"attachmentStep":false},{"name":"tmp_path_factory","time":{"start":1715477406728,"stop":1715477406728,"duration":0},"status":"passed","steps":[],"attachments":[],"parameters":[],"stepsCount":0,"shouldDisplayMessage":false,"attachmentsCount":0,"hasContent":false,"attachmentStep":false},{"name":"ops_test","time":{"start":1715477406728,"stop":1715477406856,"duration":128},"status":"passed","steps":[],"attachments":[],"parameters":[],"stepsCount":0,"shouldDisplayMessage":false,"attachmentsCount":0,"hasContent":false,"attachmentStep":false},{"name":"primary_start_timeout","time":{"start":1715478953870,"stop":1715478955949,"duration":2079},"status":"passed","steps":[],"attachments":[],"parameters":[],"stepsCount":0,"shouldDisplayMessage":false,"attachmentsCount":0,"hasContent":false,"attachmentStep":false},{"name":"abort_on_fail","time":{"start":1715480594786,"stop":1715480594786,"duration":0},"status":"passed","steps":[],"attachments":[],"parameters":[],"stepsCount":0,"shouldDisplayMessage":false,"attachmentsCount":0,"hasContent":false,"attachmentStep":false},{"name":"continuous_writes","time":{"start":1715480594786,"stop":1715480594786,"duration":0},"status":"passed","steps":[],"attachments":[],"parameters":[],"stepsCount":0,"shouldDisplayMessage":false,"attachmentsCount":0,"hasContent":false,"attachmentStep":false}],"testStage":{"description":"Completely cut and restore network (situation when the unit IP doesn't change).","status":"broken","statusMessage":"tenacity.RetryError: RetryError[<Future at 0x7f5c89b5b8e0 state=finished raised AssertionError>]","statusTrace":"Traceback (most recent call last):\n  File \"/home/runner/work/postgresql-operator/postgresql-operator/tests/integration/ha_tests/helpers.py\", line 109, in are_writes_increasing\n    more_writes[member] > count\nAssertionError: test.postgresql-2: writes not continuing to DB (current writes: 260 - previous writes: 260)\n\nThe above exception was the direct cause of the following exception:\n\nTraceback (most recent call last):\n  File \"/home/runner/work/postgresql-operator/postgresql-operator/.tox/integration/lib/python3.10/site-packages/_pytest/runner.py\", line 341, in from_call\n    result: Optional[TResult] = func()\n  File \"/home/runner/work/postgresql-operator/postgresql-operator/.tox/integration/lib/python3.10/site-packages/_pytest/runner.py\", line 241, in <lambda>\n    lambda: runtest_hook(item=item, **kwds), when=when, reraise=reraise\n  File \"/home/runner/work/postgresql-operator/postgresql-operator/.tox/integration/lib/python3.10/site-packages/pluggy/_hooks.py\", line 513, in __call__\n    return self._hookexec(self.name, self._hookimpls.copy(), kwargs, firstresult)\n  File \"/home/runner/work/postgresql-operator/postgresql-operator/.tox/integration/lib/python3.10/site-packages/pluggy/_manager.py\", line 120, in _hookexec\n    return self._inner_hookexec(hook_name, methods, kwargs, firstresult)\n  File \"/home/runner/work/postgresql-operator/postgresql-operator/.tox/integration/lib/python3.10/site-packages/pluggy/_callers.py\", line 182, in _multicall\n    return outcome.get_result()\n  File \"/home/runner/work/postgresql-operator/postgresql-operator/.tox/integration/lib/python3.10/site-packages/pluggy/_result.py\", line 100, in get_result\n    raise exc.with_traceback(exc.__traceback__)\n  File \"/home/runner/work/postgresql-operator/postgresql-operator/.tox/integration/lib/python3.10/site-packages/pluggy/_callers.py\", line 167, in _multicall\n    teardown.throw(outcome._exception)\n  File \"/home/runner/work/postgresql-operator/postgresql-operator/.tox/integration/lib/python3.10/site-packages/_pytest/threadexception.py\", line 87, in pytest_runtest_call\n    yield from thread_exception_runtest_hook()\n  File \"/home/runner/work/postgresql-operator/postgresql-operator/.tox/integration/lib/python3.10/site-packages/_pytest/threadexception.py\", line 63, in thread_exception_runtest_hook\n    yield\n  File \"/home/runner/work/postgresql-operator/postgresql-operator/.tox/integration/lib/python3.10/site-packages/pluggy/_callers.py\", line 167, in _multicall\n    teardown.throw(outcome._exception)\n  File \"/home/runner/work/postgresql-operator/postgresql-operator/.tox/integration/lib/python3.10/site-packages/_pytest/unraisableexception.py\", line 90, in pytest_runtest_call\n    yield from unraisable_exception_runtest_hook()\n  File \"/home/runner/work/postgresql-operator/postgresql-operator/.tox/integration/lib/python3.10/site-packages/_pytest/unraisableexception.py\", line 65, in unraisable_exception_runtest_hook\n    yield\n  File \"/home/runner/work/postgresql-operator/postgresql-operator/.tox/integration/lib/python3.10/site-packages/pluggy/_callers.py\", line 167, in _multicall\n    teardown.throw(outcome._exception)\n  File \"/home/runner/work/postgresql-operator/postgresql-operator/.tox/integration/lib/python3.10/site-packages/_pytest/logging.py\", line 850, in pytest_runtest_call\n    yield from self._runtest_for(item, \"call\")\n  File \"/home/runner/work/postgresql-operator/postgresql-operator/.tox/integration/lib/python3.10/site-packages/_pytest/logging.py\", line 833, in _runtest_for\n    yield\n  File \"/home/runner/work/postgresql-operator/postgresql-operator/.tox/integration/lib/python3.10/site-packages/pluggy/_callers.py\", line 167, in _multicall\n    teardown.throw(outcome._exception)\n  File \"/home/runner/work/postgresql-operator/postgresql-operator/.tox/integration/lib/python3.10/site-packages/_pytest/capture.py\", line 878, in pytest_runtest_call\n    return (yield)\n  File \"/home/runner/work/postgresql-operator/postgresql-operator/.tox/integration/lib/python3.10/site-packages/pluggy/_callers.py\", line 167, in _multicall\n    teardown.throw(outcome._exception)\n  File \"/home/runner/work/postgresql-operator/postgresql-operator/.tox/integration/lib/python3.10/site-packages/_pytest/skipping.py\", line 257, in pytest_runtest_call\n    return (yield)\n  File \"/home/runner/work/postgresql-operator/postgresql-operator/.tox/integration/lib/python3.10/site-packages/pluggy/_callers.py\", line 103, in _multicall\n    res = hook_impl.function(*args)\n  File \"/home/runner/work/postgresql-operator/postgresql-operator/.tox/integration/lib/python3.10/site-packages/_pytest/runner.py\", line 183, in pytest_runtest_call\n    raise e\n  File \"/home/runner/work/postgresql-operator/postgresql-operator/.tox/integration/lib/python3.10/site-packages/_pytest/runner.py\", line 173, in pytest_runtest_call\n    item.runtest()\n  File \"/home/runner/work/postgresql-operator/postgresql-operator/.tox/integration/lib/python3.10/site-packages/_pytest/python.py\", line 1627, in runtest\n    self.ihook.pytest_pyfunc_call(pyfuncitem=self)\n  File \"/home/runner/work/postgresql-operator/postgresql-operator/.tox/integration/lib/python3.10/site-packages/pluggy/_hooks.py\", line 513, in __call__\n    return self._hookexec(self.name, self._hookimpls.copy(), kwargs, firstresult)\n  File \"/home/runner/work/postgresql-operator/postgresql-operator/.tox/integration/lib/python3.10/site-packages/pluggy/_manager.py\", line 120, in _hookexec\n    return self._inner_hookexec(hook_name, methods, kwargs, firstresult)\n  File \"/home/runner/work/postgresql-operator/postgresql-operator/.tox/integration/lib/python3.10/site-packages/pluggy/_callers.py\", line 182, in _multicall\n    return outcome.get_result()\n  File \"/home/runner/work/postgresql-operator/postgresql-operator/.tox/integration/lib/python3.10/site-packages/pluggy/_result.py\", line 100, in get_result\n    raise exc.with_traceback(exc.__traceback__)\n  File \"/home/runner/work/postgresql-operator/postgresql-operator/.tox/integration/lib/python3.10/site-packages/pluggy/_callers.py\", line 103, in _multicall\n    res = hook_impl.function(*args)\n  File \"/home/runner/work/postgresql-operator/postgresql-operator/.tox/integration/lib/python3.10/site-packages/_pytest/python.py\", line 162, in pytest_pyfunc_call\n    result = testfunction(**testargs)\n  File \"/home/runner/work/postgresql-operator/postgresql-operator/.tox/integration/lib/python3.10/site-packages/pytest_asyncio/plugin.py\", line 529, in inner\n    _loop.run_until_complete(task)\n  File \"/usr/lib/python3.10/asyncio/base_events.py\", line 649, in run_until_complete\n    return future.result()\n  File \"/home/runner/work/postgresql-operator/postgresql-operator/tests/integration/ha_tests/test_self_healing.py\", line 518, in test_network_cut_without_ip_change\n    await are_writes_increasing(ops_test, primary_name, use_ip_from_inside=True)\n  File \"/home/runner/work/postgresql-operator/postgresql-operator/tests/integration/ha_tests/helpers.py\", line 100, in are_writes_increasing\n    for attempt in Retrying(stop=stop_after_delay(60 * 3), wait=wait_fixed(3)):\n  File \"/home/runner/work/postgresql-operator/postgresql-operator/.tox/integration/lib/python3.10/site-packages/tenacity/__init__.py\", line 347, in __iter__\n    do = self.iter(retry_state=retry_state)\n  File \"/home/runner/work/postgresql-operator/postgresql-operator/.tox/integration/lib/python3.10/site-packages/tenacity/__init__.py\", line 326, in iter\n    raise retry_exc from fut.exception()\ntenacity.RetryError: RetryError[<Future at 0x7f5c89b5b8e0 state=finished raised AssertionError>]","steps":[],"attachments":[{"uid":"219c8883c45e1f07","name":"log","source":"219c8883c45e1f07.txt","type":"text/plain","size":106222}],"parameters":[],"stepsCount":0,"shouldDisplayMessage":true,"attachmentsCount":1,"hasContent":true,"attachmentStep":false},"afterStages":[{"name":"continuous_writes::finalizer","time":{"start":1715480888934,"stop":1715481195262,"duration":306328},"status":"failed","statusMessage":"AssertionError: Unable to clear up continuous_writes table\nassert 'False' == 'True'\n  \n  - True\n  + False\n","statusTrace":"  File \"/home/runner/work/postgresql-operator/postgresql-operator/.tox/integration/lib/python3.10/site-packages/allure_commons/_allure.py\", line 221, in __call__\n    return self._fixture_function(*args, **kwargs)\n  File \"/home/runner/work/postgresql-operator/postgresql-operator/.tox/integration/lib/python3.10/site-packages/pytest_asyncio/plugin.py\", line 300, in finalizer\n    event_loop.run_until_complete(async_finalizer())\n  File \"/usr/lib/python3.10/asyncio/base_events.py\", line 649, in run_until_complete\n    return future.result()\n  File \"/home/runner/work/postgresql-operator/postgresql-operator/.tox/integration/lib/python3.10/site-packages/pytest_asyncio/plugin.py\", line 292, in async_finalizer\n    await gen_obj.__anext__()\n  File \"/home/runner/work/postgresql-operator/postgresql-operator/tests/integration/ha_tests/conftest.py\", line 29, in continuous_writes\n    for attempt in Retrying(stop=stop_after_delay(60 * 5), wait=wait_fixed(3), reraise=True):\n  File \"/home/runner/work/postgresql-operator/postgresql-operator/.tox/integration/lib/python3.10/site-packages/tenacity/__init__.py\", line 347, in __iter__\n    do = self.iter(retry_state=retry_state)\n  File \"/home/runner/work/postgresql-operator/postgresql-operator/.tox/integration/lib/python3.10/site-packages/tenacity/__init__.py\", line 325, in iter\n    raise retry_exc.reraise()\n  File \"/home/runner/work/postgresql-operator/postgresql-operator/.tox/integration/lib/python3.10/site-packages/tenacity/__init__.py\", line 158, in reraise\n    raise self.last_attempt.result()\n  File \"/usr/lib/python3.10/concurrent/futures/_base.py\", line 451, in result\n    return self.__get_result()\n  File \"/usr/lib/python3.10/concurrent/futures/_base.py\", line 403, in __get_result\n    raise self._exception\n  File \"/home/runner/work/postgresql-operator/postgresql-operator/tests/integration/ha_tests/conftest.py\", line 37, in continuous_writes\n    assert action.results[\"result\"] == \"True\", \"Unable to clear up continuous_writes table\"\n","steps":[],"attachments":[],"parameters":[],"stepsCount":0,"shouldDisplayMessage":true,"attachmentsCount":0,"hasContent":true,"attachmentStep":false},{"name":"abort_on_fail::0","time":{"start":1715481195263,"stop":1715481195263,"duration":0},"status":"passed","steps":[],"attachments":[],"parameters":[],"stepsCount":0,"shouldDisplayMessage":false,"attachmentsCount":0,"hasContent":false,"attachmentStep":false},{"name":"primary_start_timeout::finalizer","time":{"start":1715481195263,"stop":1715481205293,"duration":10030},"status":"passed","steps":[],"attachments":[],"parameters":[],"stepsCount":0,"shouldDisplayMessage":false,"attachmentsCount":0,"hasContent":false,"attachmentStep":false},{"name":"ops_test::finalizer","time":{"start":1715481205293,"stop":1715481205595,"duration":302},"status":"passed","steps":[],"attachments":[],"parameters":[],"stepsCount":0,"shouldDisplayMessage":false,"attachmentsCount":0,"hasContent":false,"attachmentStep":false},{"name":"event_loop::2","time":{"start":1715481205596,"stop":1715481205597,"duration":1},"status":"passed","steps":[],"attachments":[],"parameters":[],"stepsCount":0,"shouldDisplayMessage":false,"attachmentsCount":0,"hasContent":false,"attachmentStep":false},{"name":"event_loop::_close_event_loop","time":{"start":1715481205597,"stop":1715481205597,"duration":0},"status":"passed","steps":[],"attachments":[],"parameters":[],"stepsCount":0,"shouldDisplayMessage":false,"attachmentsCount":0,"hasContent":false,"attachmentStep":false},{"name":"event_loop::_provide_clean_event_loop","time":{"start":1715481205597,"stop":1715481205597,"duration":0},"status":"passed","steps":[],"attachments":[],"parameters":[],"stepsCount":0,"shouldDisplayMessage":false,"attachmentsCount":0,"hasContent":false,"attachmentStep":false}],"labels":[{"name":"tag","value":"group(1)"},{"name":"tag","value":"asyncio"},{"name":"parentSuite","value":"tests.integration.ha_tests"},{"name":"suite","value":"test_self_healing"},{"name":"host","value":"fv-az840-631"},{"name":"thread","value":"8228-MainThread"},{"name":"framework","value":"pytest"},{"name":"language","value":"cpython3"},{"name":"package","value":"tests.integration.ha_tests.test_self_healing"},{"name":"resultFormat","value":"allure2"}],"parameters":[],"links":[],"hidden":false,"retry":false,"extra":{"severity":"normal","retries":[],"categories":[{"name":"Test defects","matchedStatuses":[],"flaky":false}],"history":{"statistic":{"failed":6,"broken":37,"skipped":0,"passed":42,"unknown":0,"total":85},"items":[{"uid":"ca1c05648e7a949","reportUrl":"../2609//#testresult/ca1c05648e7a949","status":"passed","time":{"start":1715393730117,"stop":1715393914294,"duration":184177}},{"uid":"486f13ba9bc3bade","reportUrl":"../2603//#testresult/486f13ba9bc3bade","status":"passed","time":{"start":1715307235921,"stop":1715307425652,"duration":189731}},{"uid":"e469d294d92f1893","reportUrl":"../2599//#testresult/e469d294d92f1893","status":"broken","statusDetails":"tenacity.RetryError: RetryError[<Future at 0x7f4b638fb2b0 state=finished raised AssertionError>]","time":{"start":1715221560743,"stop":1715221783581,"duration":222838}},{"uid":"d8e0279605ddbd3f","reportUrl":"../2593//#testresult/d8e0279605ddbd3f","status":"passed","time":{"start":1715133767671,"stop":1715133962116,"duration":194445}},{"uid":"eee6bb84e008c378","reportUrl":"../2588//#testresult/eee6bb84e008c378","status":"passed","time":{"start":1715050331223,"stop":1715050534800,"duration":203577}},{"uid":"d7f9c7ce739e502b","reportUrl":"../2586//#testresult/d7f9c7ce739e502b","status":"passed","time":{"start":1714963975533,"stop":1714964157247,"duration":181714}},{"uid":"f0cc9aa723571a06","reportUrl":"../2582//#testresult/f0cc9aa723571a06","status":"broken","statusDetails":"juju.errors.JujuUnitError: Unit in error: postgresql/0","time":{"start":1714875509909,"stop":1714875635233,"duration":125324}},{"uid":"e421a4759a338cea","reportUrl":"../2581//#testresult/e421a4759a338cea","status":"broken","statusDetails":"tenacity.RetryError: RetryError[<Future at 0x7fbdcad21600 state=finished raised AssertionError>]","time":{"start":1714791052644,"stop":1714791348717,"duration":296073}},{"uid":"65cb52cbb1a3e415","reportUrl":"../2578//#testresult/65cb52cbb1a3e415","status":"passed","time":{"start":1714704282196,"stop":1714704549395,"duration":267199}},{"uid":"86c39e1c0b851b3e","reportUrl":"../2570//#testresult/86c39e1c0b851b3e","status":"broken","statusDetails":"requests.exceptions.ConnectionError: HTTPConnectionPool(host='10.8.219.218', port=8008): Max retries exceeded with url: /cluster (Caused by NewConnectionError('<urllib3.connection.HTTPConnection object at 0x7f4a82398ca0>: Failed to establish a new connection: [Errno 111] Connection refused'))","time":{"start":1714615743949,"stop":1714616543271,"duration":799322}},{"uid":"52fcb175038a9da8","reportUrl":"../2566//#testresult/52fcb175038a9da8","status":"passed","time":{"start":1714530145005,"stop":1714530334572,"duration":189567}},{"uid":"e0d70c89a0a7d6ae","reportUrl":"../2557//#testresult/e0d70c89a0a7d6ae","status":"failed","statusDetails":"AssertionError: Unable to create continuous_writes table","time":{"start":1714445203744,"stop":1714445507966,"duration":304222}},{"uid":"d1084cc449b549b1","reportUrl":"../2540//#testresult/d1084cc449b549b1","status":"failed","statusDetails":"AssertionError: Unable to create continuous_writes table","time":{"start":1714360410930,"stop":1714360719256,"duration":308326}},{"uid":"61d9659bb124ea6a","reportUrl":"../2536//#testresult/61d9659bb124ea6a","status":"broken","statusDetails":"tenacity.RetryError: RetryError[<Future at 0x7f061b7596f0 state=finished raised AssertionError>]","time":{"start":1714187227637,"stop":1714187437383,"duration":209746}},{"uid":"9c8788fc9269ccaf","reportUrl":"../2532//#testresult/9c8788fc9269ccaf","status":"passed","time":{"start":1714098614234,"stop":1714098810872,"duration":196638}},{"uid":"78278741bec825","reportUrl":"../2517//#testresult/78278741bec825","status":"passed","time":{"start":1713926144837,"stop":1713926351917,"duration":207080}},{"uid":"b19343d46ac33ce1","reportUrl":"../2503//#testresult/b19343d46ac33ce1","status":"broken","statusDetails":"requests.exceptions.ConnectionError: HTTPConnectionPool(host='10.165.35.34', port=8008): Max retries exceeded with url: /cluster (Caused by NewConnectionError('<urllib3.connection.HTTPConnection object at 0x7ffa68a67df0>: Failed to establish a new connection: [Errno 111] Connection refused'))","time":{"start":1713838108775,"stop":1713838708089,"duration":599314}},{"uid":"c15c829af493ca54","reportUrl":"../2478//#testresult/c15c829af493ca54","status":"broken","statusDetails":"requests.exceptions.ConnectionError: HTTPConnectionPool(host='10.236.177.47', port=8008): Max retries exceeded with url: /cluster (Caused by NewConnectionError('<urllib3.connection.HTTPConnection object at 0x7fe803a95e70>: Failed to establish a new connection: [Errno 111] Connection refused'))","time":{"start":1713751426984,"stop":1713752198642,"duration":771658}},{"uid":"9412fd8776bbe476","reportUrl":"../2477//#testresult/9412fd8776bbe476","status":"broken","statusDetails":"tenacity.RetryError: RetryError[<Future at 0x7fe158e55570 state=finished raised AssertionError>]","time":{"start":1713665363069,"stop":1713665660449,"duration":297380}},{"uid":"fced7dd0b8cd9c18","reportUrl":"../2474//#testresult/fced7dd0b8cd9c18","status":"broken","statusDetails":"tenacity.RetryError: RetryError[<Future at 0x7f5f2a7512d0 state=finished raised AssertionError>]","time":{"start":1713579092118,"stop":1713579388528,"duration":296410}}]},"tags":["asyncio","group(1)"]},"source":"33f3e23282d70c15.json","parameterValues":[]}