{"uid":"18b8c451b5586103","name":"test_network_cut_without_ip_change","fullName":"tests.integration.ha_tests.test_self_healing#test_network_cut_without_ip_change","historyId":"c42817a2584f9afe9bfa320de7305305","time":{"start":1709004688175,"stop":1709005892032,"duration":1203857},"description":"Completely cut and restore network (situation when the unit IP doesn't change).","descriptionHtml":"<p>Completely cut and restore network (situation when the unit IP doesn't change).</p>\n","status":"broken","statusMessage":"integration.ha_tests.helpers.ProcessError: ('Expected command %s to succeed instead it failed: %s %s', 'exec --unit postgresql/1 -- hostname -I', 1, 'ERROR timed out waiting for results from: unit postgresql/1\\n')","statusTrace":"Traceback (most recent call last):\n  File \"/home/ubuntu/github-runner/_work/postgresql-operator/postgresql-operator/.tox/integration/lib/python3.10/site-packages/_pytest/runner.py\", line 341, in from_call\n    result: Optional[TResult] = func()\n  File \"/home/ubuntu/github-runner/_work/postgresql-operator/postgresql-operator/.tox/integration/lib/python3.10/site-packages/_pytest/runner.py\", line 262, in <lambda>\n    lambda: ihook(item=item, **kwds), when=when, reraise=reraise\n  File \"/home/ubuntu/github-runner/_work/postgresql-operator/postgresql-operator/.tox/integration/lib/python3.10/site-packages/pluggy/_hooks.py\", line 493, in __call__\n    return self._hookexec(self.name, self._hookimpls, kwargs, firstresult)\n  File \"/home/ubuntu/github-runner/_work/postgresql-operator/postgresql-operator/.tox/integration/lib/python3.10/site-packages/pluggy/_manager.py\", line 115, in _hookexec\n    return self._inner_hookexec(hook_name, methods, kwargs, firstresult)\n  File \"/home/ubuntu/github-runner/_work/postgresql-operator/postgresql-operator/.tox/integration/lib/python3.10/site-packages/pluggy/_callers.py\", line 152, in _multicall\n    return outcome.get_result()\n  File \"/home/ubuntu/github-runner/_work/postgresql-operator/postgresql-operator/.tox/integration/lib/python3.10/site-packages/pluggy/_result.py\", line 114, in get_result\n    raise exc.with_traceback(exc.__traceback__)\n  File \"/home/ubuntu/github-runner/_work/postgresql-operator/postgresql-operator/.tox/integration/lib/python3.10/site-packages/pluggy/_callers.py\", line 77, in _multicall\n    res = hook_impl.function(*args)\n  File \"/home/ubuntu/github-runner/_work/postgresql-operator/postgresql-operator/.tox/integration/lib/python3.10/site-packages/_pytest/runner.py\", line 177, in pytest_runtest_call\n    raise e\n  File \"/home/ubuntu/github-runner/_work/postgresql-operator/postgresql-operator/.tox/integration/lib/python3.10/site-packages/_pytest/runner.py\", line 169, in pytest_runtest_call\n    item.runtest()\n  File \"/home/ubuntu/github-runner/_work/postgresql-operator/postgresql-operator/.tox/integration/lib/python3.10/site-packages/_pytest/python.py\", line 1792, in runtest\n    self.ihook.pytest_pyfunc_call(pyfuncitem=self)\n  File \"/home/ubuntu/github-runner/_work/postgresql-operator/postgresql-operator/.tox/integration/lib/python3.10/site-packages/pluggy/_hooks.py\", line 493, in __call__\n    return self._hookexec(self.name, self._hookimpls, kwargs, firstresult)\n  File \"/home/ubuntu/github-runner/_work/postgresql-operator/postgresql-operator/.tox/integration/lib/python3.10/site-packages/pluggy/_manager.py\", line 115, in _hookexec\n    return self._inner_hookexec(hook_name, methods, kwargs, firstresult)\n  File \"/home/ubuntu/github-runner/_work/postgresql-operator/postgresql-operator/.tox/integration/lib/python3.10/site-packages/pluggy/_callers.py\", line 152, in _multicall\n    return outcome.get_result()\n  File \"/home/ubuntu/github-runner/_work/postgresql-operator/postgresql-operator/.tox/integration/lib/python3.10/site-packages/pluggy/_result.py\", line 114, in get_result\n    raise exc.with_traceback(exc.__traceback__)\n  File \"/home/ubuntu/github-runner/_work/postgresql-operator/postgresql-operator/.tox/integration/lib/python3.10/site-packages/pluggy/_callers.py\", line 77, in _multicall\n    res = hook_impl.function(*args)\n  File \"/home/ubuntu/github-runner/_work/postgresql-operator/postgresql-operator/.tox/integration/lib/python3.10/site-packages/_pytest/python.py\", line 194, in pytest_pyfunc_call\n    result = testfunction(**testargs)\n  File \"/home/ubuntu/github-runner/_work/postgresql-operator/postgresql-operator/.tox/integration/lib/python3.10/site-packages/pytest_asyncio/plugin.py\", line 532, in inner\n    _loop.run_until_complete(task)\n  File \"/usr/lib/python3.10/asyncio/base_events.py\", line 649, in run_until_complete\n    return future.result()\n  File \"/home/ubuntu/github-runner/_work/postgresql-operator/postgresql-operator/tests/integration/ha_tests/test_self_healing.py\", line 521, in test_network_cut_without_ip_change\n    await are_writes_increasing(ops_test, primary_name, use_ip_from_inside=True)\n  File \"/home/ubuntu/github-runner/_work/postgresql-operator/postgresql-operator/tests/integration/ha_tests/helpers.py\", line 84, in are_writes_increasing\n    writes, _ = await count_writes(\n  File \"/home/ubuntu/github-runner/_work/postgresql-operator/postgresql-operator/tests/integration/ha_tests/helpers.py\", line 230, in count_writes\n    await (\n  File \"/home/ubuntu/github-runner/_work/postgresql-operator/postgresql-operator/tests/integration/ha_tests/helpers.py\", line 344, in get_ip_from_inside_the_unit\n    raise ProcessError(\nintegration.ha_tests.helpers.ProcessError: ('Expected command %s to succeed instead it failed: %s %s', 'exec --unit postgresql/1 -- hostname -I', 1, 'ERROR timed out waiting for results from: unit postgresql/1\\n')","flaky":false,"newFailed":false,"newBroken":false,"newPassed":false,"retriesCount":0,"retriesStatusChange":false,"beforeStages":[{"name":"event_loop","time":{"start":1709000682798,"stop":1709000682799,"duration":1},"status":"passed","steps":[],"attachments":[],"parameters":[],"stepsCount":0,"shouldDisplayMessage":false,"attachmentsCount":0,"hasContent":false,"attachmentStep":false},{"name":"ops_test","time":{"start":1709000682799,"stop":1709000683030,"duration":231},"status":"passed","steps":[],"attachments":[],"parameters":[],"stepsCount":0,"shouldDisplayMessage":false,"attachmentsCount":0,"hasContent":false,"attachmentStep":false},{"name":"tmp_path_factory","time":{"start":1709000682799,"stop":1709000682799,"duration":0},"status":"passed","steps":[],"attachments":[],"parameters":[],"stepsCount":0,"shouldDisplayMessage":false,"attachmentsCount":0,"hasContent":false,"attachmentStep":false},{"name":"primary_start_timeout","time":{"start":1709002712866,"stop":1709002715094,"duration":2228},"status":"passed","steps":[],"attachments":[],"parameters":[],"stepsCount":0,"shouldDisplayMessage":false,"attachmentsCount":0,"hasContent":false,"attachmentStep":false},{"name":"continuous_writes","time":{"start":1709004688173,"stop":1709004688173,"duration":0},"status":"passed","steps":[],"attachments":[],"parameters":[],"stepsCount":0,"shouldDisplayMessage":false,"attachmentsCount":0,"hasContent":false,"attachmentStep":false},{"name":"abort_on_fail","time":{"start":1709004688173,"stop":1709004688173,"duration":0},"status":"passed","steps":[],"attachments":[],"parameters":[],"stepsCount":0,"shouldDisplayMessage":false,"attachmentsCount":0,"hasContent":false,"attachmentStep":false}],"testStage":{"description":"Completely cut and restore network (situation when the unit IP doesn't change).","status":"broken","statusMessage":"integration.ha_tests.helpers.ProcessError: ('Expected command %s to succeed instead it failed: %s %s', 'exec --unit postgresql/1 -- hostname -I', 1, 'ERROR timed out waiting for results from: unit postgresql/1\\n')","statusTrace":"Traceback (most recent call last):\n  File \"/home/ubuntu/github-runner/_work/postgresql-operator/postgresql-operator/.tox/integration/lib/python3.10/site-packages/_pytest/runner.py\", line 341, in from_call\n    result: Optional[TResult] = func()\n  File \"/home/ubuntu/github-runner/_work/postgresql-operator/postgresql-operator/.tox/integration/lib/python3.10/site-packages/_pytest/runner.py\", line 262, in <lambda>\n    lambda: ihook(item=item, **kwds), when=when, reraise=reraise\n  File \"/home/ubuntu/github-runner/_work/postgresql-operator/postgresql-operator/.tox/integration/lib/python3.10/site-packages/pluggy/_hooks.py\", line 493, in __call__\n    return self._hookexec(self.name, self._hookimpls, kwargs, firstresult)\n  File \"/home/ubuntu/github-runner/_work/postgresql-operator/postgresql-operator/.tox/integration/lib/python3.10/site-packages/pluggy/_manager.py\", line 115, in _hookexec\n    return self._inner_hookexec(hook_name, methods, kwargs, firstresult)\n  File \"/home/ubuntu/github-runner/_work/postgresql-operator/postgresql-operator/.tox/integration/lib/python3.10/site-packages/pluggy/_callers.py\", line 152, in _multicall\n    return outcome.get_result()\n  File \"/home/ubuntu/github-runner/_work/postgresql-operator/postgresql-operator/.tox/integration/lib/python3.10/site-packages/pluggy/_result.py\", line 114, in get_result\n    raise exc.with_traceback(exc.__traceback__)\n  File \"/home/ubuntu/github-runner/_work/postgresql-operator/postgresql-operator/.tox/integration/lib/python3.10/site-packages/pluggy/_callers.py\", line 77, in _multicall\n    res = hook_impl.function(*args)\n  File \"/home/ubuntu/github-runner/_work/postgresql-operator/postgresql-operator/.tox/integration/lib/python3.10/site-packages/_pytest/runner.py\", line 177, in pytest_runtest_call\n    raise e\n  File \"/home/ubuntu/github-runner/_work/postgresql-operator/postgresql-operator/.tox/integration/lib/python3.10/site-packages/_pytest/runner.py\", line 169, in pytest_runtest_call\n    item.runtest()\n  File \"/home/ubuntu/github-runner/_work/postgresql-operator/postgresql-operator/.tox/integration/lib/python3.10/site-packages/_pytest/python.py\", line 1792, in runtest\n    self.ihook.pytest_pyfunc_call(pyfuncitem=self)\n  File \"/home/ubuntu/github-runner/_work/postgresql-operator/postgresql-operator/.tox/integration/lib/python3.10/site-packages/pluggy/_hooks.py\", line 493, in __call__\n    return self._hookexec(self.name, self._hookimpls, kwargs, firstresult)\n  File \"/home/ubuntu/github-runner/_work/postgresql-operator/postgresql-operator/.tox/integration/lib/python3.10/site-packages/pluggy/_manager.py\", line 115, in _hookexec\n    return self._inner_hookexec(hook_name, methods, kwargs, firstresult)\n  File \"/home/ubuntu/github-runner/_work/postgresql-operator/postgresql-operator/.tox/integration/lib/python3.10/site-packages/pluggy/_callers.py\", line 152, in _multicall\n    return outcome.get_result()\n  File \"/home/ubuntu/github-runner/_work/postgresql-operator/postgresql-operator/.tox/integration/lib/python3.10/site-packages/pluggy/_result.py\", line 114, in get_result\n    raise exc.with_traceback(exc.__traceback__)\n  File \"/home/ubuntu/github-runner/_work/postgresql-operator/postgresql-operator/.tox/integration/lib/python3.10/site-packages/pluggy/_callers.py\", line 77, in _multicall\n    res = hook_impl.function(*args)\n  File \"/home/ubuntu/github-runner/_work/postgresql-operator/postgresql-operator/.tox/integration/lib/python3.10/site-packages/_pytest/python.py\", line 194, in pytest_pyfunc_call\n    result = testfunction(**testargs)\n  File \"/home/ubuntu/github-runner/_work/postgresql-operator/postgresql-operator/.tox/integration/lib/python3.10/site-packages/pytest_asyncio/plugin.py\", line 532, in inner\n    _loop.run_until_complete(task)\n  File \"/usr/lib/python3.10/asyncio/base_events.py\", line 649, in run_until_complete\n    return future.result()\n  File \"/home/ubuntu/github-runner/_work/postgresql-operator/postgresql-operator/tests/integration/ha_tests/test_self_healing.py\", line 521, in test_network_cut_without_ip_change\n    await are_writes_increasing(ops_test, primary_name, use_ip_from_inside=True)\n  File \"/home/ubuntu/github-runner/_work/postgresql-operator/postgresql-operator/tests/integration/ha_tests/helpers.py\", line 84, in are_writes_increasing\n    writes, _ = await count_writes(\n  File \"/home/ubuntu/github-runner/_work/postgresql-operator/postgresql-operator/tests/integration/ha_tests/helpers.py\", line 230, in count_writes\n    await (\n  File \"/home/ubuntu/github-runner/_work/postgresql-operator/postgresql-operator/tests/integration/ha_tests/helpers.py\", line 344, in get_ip_from_inside_the_unit\n    raise ProcessError(\nintegration.ha_tests.helpers.ProcessError: ('Expected command %s to succeed instead it failed: %s %s', 'exec --unit postgresql/1 -- hostname -I', 1, 'ERROR timed out waiting for results from: unit postgresql/1\\n')","steps":[],"attachments":[{"uid":"79372ad0ff1ddf12","name":"log","source":"79372ad0ff1ddf12.txt","type":"text/plain","size":56840}],"parameters":[],"stepsCount":0,"shouldDisplayMessage":true,"attachmentsCount":1,"hasContent":true,"attachmentStep":false},"afterStages":[{"name":"continuous_writes::finalizer","time":{"start":1709005892045,"stop":1709006193870,"duration":301825},"status":"failed","statusMessage":"AssertionError: Unable to clear up continuous_writes table\nassert 'False' == 'True'\n  - True\n  + False\n","statusTrace":"  File \"/home/ubuntu/github-runner/_work/postgresql-operator/postgresql-operator/.tox/integration/lib/python3.10/site-packages/allure_commons/_allure.py\", line 221, in __call__\n    return self._fixture_function(*args, **kwargs)\n  File \"/home/ubuntu/github-runner/_work/postgresql-operator/postgresql-operator/.tox/integration/lib/python3.10/site-packages/pytest_asyncio/plugin.py\", line 302, in finalizer\n    event_loop.run_until_complete(async_finalizer())\n  File \"/usr/lib/python3.10/asyncio/base_events.py\", line 649, in run_until_complete\n    return future.result()\n  File \"/home/ubuntu/github-runner/_work/postgresql-operator/postgresql-operator/.tox/integration/lib/python3.10/site-packages/pytest_asyncio/plugin.py\", line 294, in async_finalizer\n    await gen_obj.__anext__()\n  File \"/home/ubuntu/github-runner/_work/postgresql-operator/postgresql-operator/tests/integration/ha_tests/conftest.py\", line 29, in continuous_writes\n    for attempt in Retrying(stop=stop_after_delay(60 * 5), wait=wait_fixed(3), reraise=True):\n  File \"/home/ubuntu/github-runner/_work/postgresql-operator/postgresql-operator/.tox/integration/lib/python3.10/site-packages/tenacity/__init__.py\", line 347, in __iter__\n    do = self.iter(retry_state=retry_state)\n  File \"/home/ubuntu/github-runner/_work/postgresql-operator/postgresql-operator/.tox/integration/lib/python3.10/site-packages/tenacity/__init__.py\", line 325, in iter\n    raise retry_exc.reraise()\n  File \"/home/ubuntu/github-runner/_work/postgresql-operator/postgresql-operator/.tox/integration/lib/python3.10/site-packages/tenacity/__init__.py\", line 158, in reraise\n    raise self.last_attempt.result()\n  File \"/usr/lib/python3.10/concurrent/futures/_base.py\", line 451, in result\n    return self.__get_result()\n  File \"/usr/lib/python3.10/concurrent/futures/_base.py\", line 403, in __get_result\n    raise self._exception\n  File \"/home/ubuntu/github-runner/_work/postgresql-operator/postgresql-operator/tests/integration/ha_tests/conftest.py\", line 37, in continuous_writes\n    assert action.results[\"result\"] == \"True\", \"Unable to clear up continuous_writes table\"\n","steps":[],"attachments":[],"parameters":[],"stepsCount":0,"shouldDisplayMessage":true,"attachmentsCount":0,"hasContent":true,"attachmentStep":false},{"name":"abort_on_fail::0","time":{"start":1709006193876,"stop":1709006193877,"duration":1},"status":"passed","steps":[],"attachments":[],"parameters":[],"stepsCount":0,"shouldDisplayMessage":false,"attachmentsCount":0,"hasContent":false,"attachmentStep":false},{"name":"primary_start_timeout::finalizer","time":{"start":1709006193878,"stop":1709006333349,"duration":139471},"status":"broken","statusMessage":"tenacity.RetryError: RetryError[<Future at 0x7f63f25869e0 state=finished raised ConnectTimeout>]\n","statusTrace":"  File \"/home/ubuntu/github-runner/_work/postgresql-operator/postgresql-operator/.tox/integration/lib/python3.10/site-packages/allure_commons/_allure.py\", line 221, in __call__\n    return self._fixture_function(*args, **kwargs)\n  File \"/home/ubuntu/github-runner/_work/postgresql-operator/postgresql-operator/.tox/integration/lib/python3.10/site-packages/pytest_asyncio/plugin.py\", line 302, in finalizer\n    event_loop.run_until_complete(async_finalizer())\n  File \"/usr/lib/python3.10/asyncio/base_events.py\", line 649, in run_until_complete\n    return future.result()\n  File \"/home/ubuntu/github-runner/_work/postgresql-operator/postgresql-operator/.tox/integration/lib/python3.10/site-packages/pytest_asyncio/plugin.py\", line 294, in async_finalizer\n    await gen_obj.__anext__()\n  File \"/home/ubuntu/github-runner/_work/postgresql-operator/postgresql-operator/tests/integration/ha_tests/conftest.py\", line 58, in primary_start_timeout\n    await change_patroni_setting(\n  File \"/home/ubuntu/github-runner/_work/postgresql-operator/postgresql-operator/tests/integration/ha_tests/helpers.py\", line 129, in change_patroni_setting\n    for attempt in Retrying(stop=stop_after_delay(30 * 2), wait=wait_fixed(3)):\n  File \"/home/ubuntu/github-runner/_work/postgresql-operator/postgresql-operator/.tox/integration/lib/python3.10/site-packages/tenacity/__init__.py\", line 347, in __iter__\n    do = self.iter(retry_state=retry_state)\n  File \"/home/ubuntu/github-runner/_work/postgresql-operator/postgresql-operator/.tox/integration/lib/python3.10/site-packages/tenacity/__init__.py\", line 326, in iter\n    raise retry_exc from fut.exception()\n","steps":[],"attachments":[],"parameters":[],"stepsCount":0,"shouldDisplayMessage":true,"attachmentsCount":0,"hasContent":true,"attachmentStep":false},{"name":"ops_test::finalizer","time":{"start":1709006333359,"stop":1709006334040,"duration":681},"status":"passed","steps":[],"attachments":[],"parameters":[],"stepsCount":0,"shouldDisplayMessage":false,"attachmentsCount":0,"hasContent":false,"attachmentStep":false},{"name":"event_loop::2","time":{"start":1709006334045,"stop":1709006334047,"duration":2},"status":"passed","steps":[],"attachments":[],"parameters":[],"stepsCount":0,"shouldDisplayMessage":false,"attachmentsCount":0,"hasContent":false,"attachmentStep":false},{"name":"event_loop::_close_event_loop","time":{"start":1709006334047,"stop":1709006334047,"duration":0},"status":"passed","steps":[],"attachments":[],"parameters":[],"stepsCount":0,"shouldDisplayMessage":false,"attachmentsCount":0,"hasContent":false,"attachmentStep":false},{"name":"event_loop::_provide_clean_event_loop","time":{"start":1709006334047,"stop":1709006334048,"duration":1},"status":"passed","steps":[],"attachments":[],"parameters":[],"stepsCount":0,"shouldDisplayMessage":false,"attachmentsCount":0,"hasContent":false,"attachmentStep":false}],"labels":[{"name":"tag","value":"group(1)"},{"name":"tag","value":"asyncio"},{"name":"parentSuite","value":"tests.integration.ha_tests"},{"name":"suite","value":"test_self_healing"},{"name":"host","value":"large-265-f3198d40120af35680e4c13e"},{"name":"thread","value":"7568-MainThread"},{"name":"framework","value":"pytest"},{"name":"language","value":"cpython3"},{"name":"package","value":"tests.integration.ha_tests.test_self_healing"},{"name":"resultFormat","value":"allure2"}],"parameters":[],"links":[],"hidden":false,"retry":false,"extra":{"severity":"normal","retries":[],"categories":[{"name":"Test defects","matchedStatuses":[],"flaky":false}],"history":{"statistic":{"failed":2,"broken":11,"skipped":0,"passed":12,"unknown":0,"total":25},"items":[{"uid":"cf11cb18f7f3d6e7","reportUrl":"../2061//#testresult/cf11cb18f7f3d6e7","status":"broken","statusDetails":"tenacity.RetryError: RetryError[<Future at 0x7f64e6087fd0 state=finished raised AssertionError>]","time":{"start":1708742127637,"stop":1708742468365,"duration":340728}},{"uid":"582f483ef7c40fa5","reportUrl":"../2055//#testresult/582f483ef7c40fa5","status":"broken","statusDetails":"asyncio.exceptions.TimeoutError: Timed out waiting for model:\npostgresql/1 [idle] waiting: awaiting for member to start\n  postgresql/2 [idle] active: \n  postgresql/3 [idle] active: Primary","time":{"start":1708656282934,"stop":1708657042675,"duration":759741}},{"uid":"189a3ded2d9777f2","reportUrl":"../2032//#testresult/189a3ded2d9777f2","status":"passed","time":{"start":1708483008712,"stop":1708483222129,"duration":213417}},{"uid":"2e047bf5493e0705","reportUrl":"../2027//#testresult/2e047bf5493e0705","status":"passed","time":{"start":1708397302265,"stop":1708397552772,"duration":250507}},{"uid":"d0b5e3ca2fe117ca","reportUrl":"../2025//#testresult/d0b5e3ca2fe117ca","status":"passed","time":{"start":1708311381702,"stop":1708311626524,"duration":244822}},{"uid":"4f692ba45da834e4","reportUrl":"../2019//#testresult/4f692ba45da834e4","status":"passed","time":{"start":1708137198782,"stop":1708137427131,"duration":228349}},{"uid":"ca0fc0440fb9a732","reportUrl":"../2013//#testresult/ca0fc0440fb9a732","status":"passed","time":{"start":1708051745372,"stop":1708051968971,"duration":223599}},{"uid":"c6d608033140bcab","reportUrl":"../2008//#testresult/c6d608033140bcab","status":"broken","statusDetails":"tenacity.RetryError: RetryError[<Future at 0x7f4c31115c00 state=finished raised AssertionError>]","time":{"start":1707965697386,"stop":1707966140579,"duration":443193}},{"uid":"e3d0482403d52c8f","reportUrl":"../2000//#testresult/e3d0482403d52c8f","status":"passed","time":{"start":1707791361623,"stop":1707791573719,"duration":212096}},{"uid":"5eaaed0be0779982","reportUrl":"../1996//#testresult/5eaaed0be0779982","status":"passed","time":{"start":1707706399126,"stop":1707706649242,"duration":250116}},{"uid":"32f6287576c4de11","reportUrl":"../1995//#testresult/32f6287576c4de11","status":"broken","statusDetails":"tenacity.RetryError: RetryError[<Future at 0x7fadf9513280 state=finished raised AssertionError>]","time":{"start":1707619096343,"stop":1707619681665,"duration":585322}},{"uid":"a3a22b472baa3713","reportUrl":"../1990//#testresult/a3a22b472baa3713","status":"broken","statusDetails":"requests.exceptions.ConnectionError: HTTPConnectionPool(host='10.17.57.115', port=8008): Max retries exceeded with url: /cluster (Caused by NewConnectionError('<urllib3.connection.HTTPConnection object at 0x7f0782895cf0>: Failed to establish a new connection: [Errno 113] No route to host'))","time":{"start":1707445759042,"stop":1707446295456,"duration":536414}},{"uid":"d0d2e41b7e58d946","reportUrl":"../1988//#testresult/d0d2e41b7e58d946","status":"broken","statusDetails":"tenacity.RetryError: RetryError[<Future at 0x7fe509d2a7d0 state=finished raised AssertionError>]","time":{"start":1707361573209,"stop":1707361755576,"duration":182367}},{"uid":"4d5babba0f5fa701","reportUrl":"../1973//#testresult/4d5babba0f5fa701","status":"passed","time":{"start":1707272808910,"stop":1707272930563,"duration":121653}},{"uid":"c0d02bdcd22ae49b","reportUrl":"../1961//#testresult/c0d02bdcd22ae49b","status":"broken","statusDetails":"tenacity.RetryError: RetryError[<Future at 0x7f1087984670 state=finished raised RetryError>]","time":{"start":1707185679734,"stop":1707188659760,"duration":2980026}},{"uid":"be12ba85ad071b1b","reportUrl":"../1957//#testresult/be12ba85ad071b1b","status":"broken","statusDetails":"tenacity.RetryError: RetryError[<Future at 0x7f493c06e3e0 state=finished raised AssertionError>]","time":{"start":1707099962754,"stop":1707100506395,"duration":543641}},{"uid":"81d6edc6051d7ab4","reportUrl":"../1956//#testresult/81d6edc6051d7ab4","status":"failed","statusDetails":"AssertionError: Unable to create continuous_writes table","time":{"start":1707013593708,"stop":1707013897213,"duration":303505}},{"uid":"31e87595b4ea21c7","reportUrl":"../1955//#testresult/31e87595b4ea21c7","status":"passed","time":{"start":1706928097116,"stop":1706928265961,"duration":168845}},{"uid":"2e33508a1400be5f","reportUrl":"../1939//#testresult/2e33508a1400be5f","status":"broken","statusDetails":"requests.exceptions.ConnectionError: HTTPConnectionPool(host='10.176.153.120', port=8008): Max retries exceeded with url: /cluster (Caused by NewConnectionError('<urllib3.connection.HTTPConnection object at 0x7f45d1c05180>: Failed to establish a new connection: [Errno 111] Connection refused'))","time":{"start":1706754611736,"stop":1706755019668,"duration":407932}},{"uid":"9199e4e1631b2db7","reportUrl":"../1935//#testresult/9199e4e1631b2db7","status":"failed","statusDetails":"AssertionError: Unable to create continuous_writes table","time":{"start":1706674274559,"stop":1706674577753,"duration":303194}}]},"tags":["asyncio","group(1)"]},"source":"18b8c451b5586103.json","parameterValues":[]}